2020-12-09 21:58:54,162 ERROR: Exception on /user/zaid [GET] [in c:\users\ijaz bacha\project\microblog1\venv\lib\site-packages\flask\app.py:1891]
Traceback (most recent call last):
  File "c:\users\ijaz bacha\project\microblog1\venv\lib\site-packages\flask\app.py", line 2447, in wsgi_app
    response = self.full_dispatch_request()
  File "c:\users\ijaz bacha\project\microblog1\venv\lib\site-packages\flask\app.py", line 1952, in full_dispatch_request
    rv = self.handle_user_exception(e)
  File "c:\users\ijaz bacha\project\microblog1\venv\lib\site-packages\flask\app.py", line 1821, in handle_user_exception
    reraise(exc_type, exc_value, tb)
  File "c:\users\ijaz bacha\project\microblog1\venv\lib\site-packages\flask\_compat.py", line 39, in reraise
    raise value
  File "c:\users\ijaz bacha\project\microblog1\venv\lib\site-packages\flask\app.py", line 1948, in full_dispatch_request
    rv = self.preprocess_request()
  File "c:\users\ijaz bacha\project\microblog1\venv\lib\site-packages\flask\app.py", line 2242, in preprocess_request
    rv = func()
  File "C:\Users\Ijaz Bacha\project\microblog1\app\main\routes.py", line 15, in before_request
    if current_user.is_authenticated:
  File "c:\users\ijaz bacha\project\microblog1\venv\lib\site-packages\werkzeug\local.py", line 347, in __getattr__
    return getattr(self._get_current_object(), name)
  File "c:\users\ijaz bacha\project\microblog1\venv\lib\site-packages\werkzeug\local.py", line 306, in _get_current_object
    return self.__local()
  File "c:\users\ijaz bacha\project\microblog1\venv\lib\site-packages\flask_login\utils.py", line 26, in <lambda>
    current_user = LocalProxy(lambda: _get_user())
  File "c:\users\ijaz bacha\project\microblog1\venv\lib\site-packages\flask_login\utils.py", line 346, in _get_user
    current_app.login_manager._load_user()
  File "c:\users\ijaz bacha\project\microblog1\venv\lib\site-packages\flask_login\login_manager.py", line 318, in _load_user
    user = self._user_callback(user_id)
  File "C:\Users\Ijaz Bacha\project\microblog1\app\models.py", line 140, in load_user
    return User.query.get(int(id))
  File "c:\users\ijaz bacha\project\microblog1\venv\lib\site-packages\flask_sqlalchemy\__init__.py", line 512, in __get__
    mapper = orm.class_mapper(type)
  File "c:\users\ijaz bacha\project\microblog1\venv\lib\site-packages\sqlalchemy\orm\base.py", line 451, in class_mapper
    mapper = _inspect_mapped_class(class_, configure=configure)
  File "c:\users\ijaz bacha\project\microblog1\venv\lib\site-packages\sqlalchemy\orm\base.py", line 430, in _inspect_mapped_class
    mapper._configure_all()
  File "c:\users\ijaz bacha\project\microblog1\venv\lib\site-packages\sqlalchemy\orm\mapper.py", line 1352, in _configure_all
    configure_mappers()
  File "c:\users\ijaz bacha\project\microblog1\venv\lib\site-packages\sqlalchemy\orm\mapper.py", line 3295, in configure_mappers
    raise e
sqlalchemy.exc.InvalidRequestError: One or more mappers failed to initialize - can't proceed with initialization of other mappers. Triggering mapper: 'mapped class User->user'. Original exception was: 'Table' object has no attribute 'sender_id'
2020-12-09 22:15:53,606 INFO: Microblog startup [in C:\Users\Ijaz Bacha\project\microblog1\app\__init__.py:84]
2020-12-09 22:15:59,931 ERROR: Exception on / [GET] [in c:\users\ijaz bacha\project\microblog1\venv\lib\site-packages\flask\app.py:1891]
Traceback (most recent call last):
  File "c:\users\ijaz bacha\project\microblog1\venv\lib\site-packages\flask\app.py", line 2447, in wsgi_app
    response = self.full_dispatch_request()
  File "c:\users\ijaz bacha\project\microblog1\venv\lib\site-packages\flask\app.py", line 1952, in full_dispatch_request
    rv = self.handle_user_exception(e)
  File "c:\users\ijaz bacha\project\microblog1\venv\lib\site-packages\flask\app.py", line 1821, in handle_user_exception
    reraise(exc_type, exc_value, tb)
  File "c:\users\ijaz bacha\project\microblog1\venv\lib\site-packages\flask\_compat.py", line 39, in reraise
    raise value
  File "c:\users\ijaz bacha\project\microblog1\venv\lib\site-packages\flask\app.py", line 1948, in full_dispatch_request
    rv = self.preprocess_request()
  File "c:\users\ijaz bacha\project\microblog1\venv\lib\site-packages\flask\app.py", line 2242, in preprocess_request
    rv = func()
  File "C:\Users\Ijaz Bacha\project\microblog1\app\main\routes.py", line 15, in before_request
    if current_user.is_authenticated:
  File "c:\users\ijaz bacha\project\microblog1\venv\lib\site-packages\werkzeug\local.py", line 347, in __getattr__
    return getattr(self._get_current_object(), name)
  File "c:\users\ijaz bacha\project\microblog1\venv\lib\site-packages\werkzeug\local.py", line 306, in _get_current_object
    return self.__local()
  File "c:\users\ijaz bacha\project\microblog1\venv\lib\site-packages\flask_login\utils.py", line 26, in <lambda>
    current_user = LocalProxy(lambda: _get_user())
  File "c:\users\ijaz bacha\project\microblog1\venv\lib\site-packages\flask_login\utils.py", line 346, in _get_user
    current_app.login_manager._load_user()
  File "c:\users\ijaz bacha\project\microblog1\venv\lib\site-packages\flask_login\login_manager.py", line 318, in _load_user
    user = self._user_callback(user_id)
  File "C:\Users\Ijaz Bacha\project\microblog1\app\models.py", line 140, in load_user
    return User.query.get(int(id))
  File "c:\users\ijaz bacha\project\microblog1\venv\lib\site-packages\flask_sqlalchemy\__init__.py", line 512, in __get__
    mapper = orm.class_mapper(type)
  File "c:\users\ijaz bacha\project\microblog1\venv\lib\site-packages\sqlalchemy\orm\base.py", line 451, in class_mapper
    mapper = _inspect_mapped_class(class_, configure=configure)
  File "c:\users\ijaz bacha\project\microblog1\venv\lib\site-packages\sqlalchemy\orm\base.py", line 430, in _inspect_mapped_class
    mapper._configure_all()
  File "c:\users\ijaz bacha\project\microblog1\venv\lib\site-packages\sqlalchemy\orm\mapper.py", line 1352, in _configure_all
    configure_mappers()
  File "c:\users\ijaz bacha\project\microblog1\venv\lib\site-packages\sqlalchemy\orm\mapper.py", line 3299, in configure_mappers
    mapper._post_configure_properties()
  File "c:\users\ijaz bacha\project\microblog1\venv\lib\site-packages\sqlalchemy\orm\mapper.py", line 1965, in _post_configure_properties
    prop.init()
  File "c:\users\ijaz bacha\project\microblog1\venv\lib\site-packages\sqlalchemy\orm\interfaces.py", line 197, in init
    self.do_init()
  File "c:\users\ijaz bacha\project\microblog1\venv\lib\site-packages\sqlalchemy\orm\relationships.py", line 2076, in do_init
    self._process_dependent_arguments()
  File "c:\users\ijaz bacha\project\microblog1\venv\lib\site-packages\sqlalchemy\orm\relationships.py", line 2105, in _process_dependent_arguments
    setattr(self, attr, attr_value())
  File "c:\users\ijaz bacha\project\microblog1\venv\lib\site-packages\sqlalchemy\ext\declarative\clsregistry.py", line 326, in __call__
    x = eval(self.arg, globals(), self._dict)
  File "<string>", line 1, in <module>
AttributeError: 'Table' object has no attribute 'sender_id'
2020-12-10 08:37:02,268 INFO: Microblog startup [in C:\Users\Ijaz Bacha\project\microblog1\app\__init__.py:84]
2020-12-10 09:02:49,232 INFO: Microblog startup [in C:\Users\Ijaz Bacha\project\microblog1\app\__init__.py:84]
2020-12-10 10:07:30,867 INFO: Microblog startup [in C:\Users\Ijaz Bacha\project\microblog1\app\__init__.py:84]
2020-12-10 10:22:46,942 INFO: Microblog startup [in C:\Users\Ijaz Bacha\project\microblog1\app\__init__.py:84]
2020-12-12 10:14:33,596 INFO: Microblog startup [in C:\Users\Ijaz Bacha\project\microblog1\app\__init__.py:87]
2020-12-12 10:15:08,735 INFO: Microblog startup [in C:\Users\Ijaz Bacha\project\microblog1\app\__init__.py:87]
2020-12-12 11:36:09,737 INFO: Microblog startup [in C:\Users\Ijaz Bacha\project\microblog1\app\__init__.py:99]
2020-12-12 11:51:31,886 INFO: Microblog startup [in C:\Users\Ijaz Bacha\project\microblog1\app\__init__.py:99]
2020-12-12 12:03:04,601 INFO: Microblog startup [in C:\Users\Ijaz Bacha\project\microblog1\app\__init__.py:99]
2020-12-12 13:00:54,051 INFO: Microblog startup [in C:\Users\Ijaz Bacha\project\microblog1\app\__init__.py:106]
2020-12-12 13:10:50,000 INFO: Microblog startup [in C:\Users\Ijaz Bacha\project\microblog1\app\__init__.py:106]
2020-12-12 13:11:25,773 ERROR: Exception on /auth/reset_password/eyJ0eXAiOiJKV1QiLCJhbGciOiJIUzI1NiJ9.eyJyZXNldF9wYXNzd29yZCI6NiwiZXhwIjoxNjA3NzYxMjYyLjcxMjM5Mjh9.o3yU0gkg3vekUyryGn_1YgtNQjkIZatFsbsgpsTohGM [GET] [in c:\users\ijaz bacha\project\microblog1\venv\lib\site-packages\flask\app.py:1891]
Traceback (most recent call last):
  File "c:\users\ijaz bacha\project\microblog1\venv\lib\site-packages\flask\app.py", line 2447, in wsgi_app
    response = self.full_dispatch_request()
  File "c:\users\ijaz bacha\project\microblog1\venv\lib\site-packages\flask\app.py", line 1952, in full_dispatch_request
    rv = self.handle_user_exception(e)
  File "c:\users\ijaz bacha\project\microblog1\venv\lib\site-packages\flask\app.py", line 1821, in handle_user_exception
    reraise(exc_type, exc_value, tb)
  File "c:\users\ijaz bacha\project\microblog1\venv\lib\site-packages\flask\_compat.py", line 39, in reraise
    raise value
  File "c:\users\ijaz bacha\project\microblog1\venv\lib\site-packages\flask\app.py", line 1950, in full_dispatch_request
    rv = self.dispatch_request()
  File "c:\users\ijaz bacha\project\microblog1\venv\lib\site-packages\flask\app.py", line 1936, in dispatch_request
    return self.view_functions[rule.endpoint](**req.view_args)
  File "C:\Users\Ijaz Bacha\project\microblog1\app\auth\routes.py", line 73, in reset_password
    user = User.verify_reset_password_token(token)
AttributeError: type object 'User' has no attribute 'verify_reset_password_token'
