2020-12-12 13:14:41,773 ERROR: Exception on /auth/reset_password/eyJ0eXAiOiJKV1QiLCJhbGciOiJIUzI1NiJ9.eyJyZXNldF9wYXNzd29yZCI6NiwiZXhwIjoxNjA3NzYxNDUyLjk3MTk3NjV9.azeJGbpxiKSTg_cIJmr85FXvRHHPv7JYkgxTthlkFpk [GET] [in c:\users\ijaz bacha\project\microblog1\venv\lib\site-packages\flask\app.py:1891]
Traceback (most recent call last):
  File "c:\users\ijaz bacha\project\microblog1\venv\lib\site-packages\flask\app.py", line 2447, in wsgi_app
    response = self.full_dispatch_request()
  File "c:\users\ijaz bacha\project\microblog1\venv\lib\site-packages\flask\app.py", line 1952, in full_dispatch_request
    rv = self.handle_user_exception(e)
  File "c:\users\ijaz bacha\project\microblog1\venv\lib\site-packages\flask\app.py", line 1821, in handle_user_exception
    reraise(exc_type, exc_value, tb)
  File "c:\users\ijaz bacha\project\microblog1\venv\lib\site-packages\flask\_compat.py", line 39, in reraise
    raise value
  File "c:\users\ijaz bacha\project\microblog1\venv\lib\site-packages\flask\app.py", line 1950, in full_dispatch_request
    rv = self.dispatch_request()
  File "c:\users\ijaz bacha\project\microblog1\venv\lib\site-packages\flask\app.py", line 1936, in dispatch_request
    return self.view_functions[rule.endpoint](**req.view_args)
  File "C:\Users\Ijaz Bacha\project\microblog1\app\auth\routes.py", line 73, in reset_password
    user = User.verify_reset_password_token(token)
AttributeError: type object 'User' has no attribute 'verify_reset_password_token'
2020-12-12 13:24:32,378 INFO: Microblog startup [in C:\Users\Ijaz Bacha\project\microblog1\app\__init__.py:106]
2020-12-12 13:25:40,776 INFO: Microblog startup [in C:\Users\Ijaz Bacha\project\microblog1\app\__init__.py:106]
2020-12-12 13:25:49,911 ERROR: Exception on /auth/reset_password_request [POST] [in c:\users\ijaz bacha\project\microblog1\venv\lib\site-packages\flask\app.py:1891]
Traceback (most recent call last):
  File "c:\users\ijaz bacha\project\microblog1\venv\lib\site-packages\flask\app.py", line 2447, in wsgi_app
    response = self.full_dispatch_request()
  File "c:\users\ijaz bacha\project\microblog1\venv\lib\site-packages\flask\app.py", line 1952, in full_dispatch_request
    rv = self.handle_user_exception(e)
  File "c:\users\ijaz bacha\project\microblog1\venv\lib\site-packages\flask\app.py", line 1821, in handle_user_exception
    reraise(exc_type, exc_value, tb)
  File "c:\users\ijaz bacha\project\microblog1\venv\lib\site-packages\flask\_compat.py", line 39, in reraise
    raise value
  File "c:\users\ijaz bacha\project\microblog1\venv\lib\site-packages\flask\app.py", line 1950, in full_dispatch_request
    rv = self.dispatch_request()
  File "c:\users\ijaz bacha\project\microblog1\venv\lib\site-packages\flask\app.py", line 1936, in dispatch_request
    return self.view_functions[rule.endpoint](**req.view_args)
  File "C:\Users\Ijaz Bacha\project\microblog1\app\auth\routes.py", line 61, in reset_password_request
    send_password_reset_email(user)
  File "C:\Users\Ijaz Bacha\project\microblog1\app\auth\email.py", line 9, in send_password_reset_email
    sender=current_app.config['ADMINS'][0],
KeyError: 'ADMINS'
2020-12-12 13:26:15,912 ERROR: Exception on /auth/reset_password_request [POST] [in c:\users\ijaz bacha\project\microblog1\venv\lib\site-packages\flask\app.py:1891]
Traceback (most recent call last):
  File "c:\users\ijaz bacha\project\microblog1\venv\lib\site-packages\flask\app.py", line 2447, in wsgi_app
    response = self.full_dispatch_request()
  File "c:\users\ijaz bacha\project\microblog1\venv\lib\site-packages\flask\app.py", line 1952, in full_dispatch_request
    rv = self.handle_user_exception(e)
  File "c:\users\ijaz bacha\project\microblog1\venv\lib\site-packages\flask\app.py", line 1821, in handle_user_exception
    reraise(exc_type, exc_value, tb)
  File "c:\users\ijaz bacha\project\microblog1\venv\lib\site-packages\flask\_compat.py", line 39, in reraise
    raise value
  File "c:\users\ijaz bacha\project\microblog1\venv\lib\site-packages\flask\app.py", line 1950, in full_dispatch_request
    rv = self.dispatch_request()
  File "c:\users\ijaz bacha\project\microblog1\venv\lib\site-packages\flask\app.py", line 1936, in dispatch_request
    return self.view_functions[rule.endpoint](**req.view_args)
  File "C:\Users\Ijaz Bacha\project\microblog1\app\auth\routes.py", line 61, in reset_password_request
    send_password_reset_email(user)
  File "C:\Users\Ijaz Bacha\project\microblog1\app\auth\email.py", line 9, in send_password_reset_email
    sender=current_app.config['ADMINS'][0],
KeyError: 'ADMINS'
2020-12-12 13:26:34,197 INFO: Microblog startup [in C:\Users\Ijaz Bacha\project\microblog1\app\__init__.py:106]
2020-12-12 13:27:07,269 ERROR: Exception on /auth/reset_password/eyJ0eXAiOiJKV1QiLCJhbGciOiJIUzI1NiJ9.eyJyZXNldF9wYXNzd29yZCI6NSwiZXhwIjoxNjA3NzYyMjAzLjQ4NzY0OTJ9.DAoRWLNVbRhrJPURNpmTK89b6kZXCyLM2vusvvTANSQ [GET] [in c:\users\ijaz bacha\project\microblog1\venv\lib\site-packages\flask\app.py:1891]
Traceback (most recent call last):
  File "c:\users\ijaz bacha\project\microblog1\venv\lib\site-packages\flask\app.py", line 2447, in wsgi_app
    response = self.full_dispatch_request()
  File "c:\users\ijaz bacha\project\microblog1\venv\lib\site-packages\flask\app.py", line 1952, in full_dispatch_request
    rv = self.handle_user_exception(e)
  File "c:\users\ijaz bacha\project\microblog1\venv\lib\site-packages\flask\app.py", line 1821, in handle_user_exception
    reraise(exc_type, exc_value, tb)
  File "c:\users\ijaz bacha\project\microblog1\venv\lib\site-packages\flask\_compat.py", line 39, in reraise
    raise value
  File "c:\users\ijaz bacha\project\microblog1\venv\lib\site-packages\flask\app.py", line 1950, in full_dispatch_request
    rv = self.dispatch_request()
  File "c:\users\ijaz bacha\project\microblog1\venv\lib\site-packages\flask\app.py", line 1936, in dispatch_request
    return self.view_functions[rule.endpoint](**req.view_args)
  File "C:\Users\Ijaz Bacha\project\microblog1\app\auth\routes.py", line 73, in reset_password
    user = User.verify_reset_password_token(token)
AttributeError: type object 'User' has no attribute 'verify_reset_password_token'
2020-12-12 13:29:06,102 ERROR: Exception on /auth/reset_password/eyJ0eXAiOiJKV1QiLCJhbGciOiJIUzI1NiJ9.eyJyZXNldF9wYXNzd29yZCI6NiwiZXhwIjoxNjA3NzYxMjYyLjcxMjM5Mjh9.o3yU0gkg3vekUyryGn_1YgtNQjkIZatFsbsgpsTohGM [GET] [in c:\users\ijaz bacha\project\microblog1\venv\lib\site-packages\flask\app.py:1891]
Traceback (most recent call last):
  File "c:\users\ijaz bacha\project\microblog1\venv\lib\site-packages\flask\app.py", line 2447, in wsgi_app
    response = self.full_dispatch_request()
  File "c:\users\ijaz bacha\project\microblog1\venv\lib\site-packages\flask\app.py", line 1952, in full_dispatch_request
    rv = self.handle_user_exception(e)
  File "c:\users\ijaz bacha\project\microblog1\venv\lib\site-packages\flask\app.py", line 1821, in handle_user_exception
    reraise(exc_type, exc_value, tb)
  File "c:\users\ijaz bacha\project\microblog1\venv\lib\site-packages\flask\_compat.py", line 39, in reraise
    raise value
  File "c:\users\ijaz bacha\project\microblog1\venv\lib\site-packages\flask\app.py", line 1950, in full_dispatch_request
    rv = self.dispatch_request()
  File "c:\users\ijaz bacha\project\microblog1\venv\lib\site-packages\flask\app.py", line 1936, in dispatch_request
    return self.view_functions[rule.endpoint](**req.view_args)
  File "C:\Users\Ijaz Bacha\project\microblog1\app\auth\routes.py", line 73, in reset_password
    user = User.verify_reset_password_token(token)
AttributeError: type object 'User' has no attribute 'verify_reset_password_token'
